Workbook

Sheet KLASA A
A1: KLASA A | B1: liczba uczniów | C1: 25
A3: Zadanie | B3: 1 | C3: 2 | D3: 3 | E3: 4 | F3: 5 | G3: 6 | H3: 7 | I3: 8 | J3: 9 | K3: 10 | L3: 11 | M3: 12 | N3: 13 | O3: 14 | P3: 15 | Q3: 16 | R3: 17 | S3: 18 | T3: 19 | U3: 20 | V3: 21 I | W3: 21 II | X3: 22 I | Y3: 22 II | Z3: 23 | AA3: 24 | AB3: 25
A4: Standard | B4: I | C4: I | D4: I | E4: I | F4: III | G4: IV | H4: IV | I4: V | J4: V | K4: III | L4: III | M4: V | N4: V | O4: I | P4: I | Q4: I | R4: IV | S4: III | T4: V | U4: V | V4: III | W4: V | X4: III | Y4: V | Z4: I | AA4: I | AB4: II
A5: Max liczba punktów | B5: 1 | C5: 1 | D5: 1 | E5: 1 | F5: 1 | G5: 1 | H5: 2 | I5: 1 | J5: 1 | K5: 1 | L5: 1 | M5: 1 | N5: 1 | O5: 1 | P5: 1 | Q5: 1 | R5: 1 | S5: 1 | T5: 1 | U5: 1 | V5: 3 | W5: 1 | X5: 2 | Y5: 2 | Z5: 2 | AA5: 1 | AB5: 8 | AC5: suma | AD5: procent
A6: A01 | B6: 1 | C6: 1 | D6: 1 | E6: 1 | F6: 1 | G6: 1 | H6: 2 | I6: 1 | J6: 1 | K6: 1 | L6: 1 | M6: 1 | N6: 1 | O6: 1 | P6: 1 | Q6: 1 | R6: 1 | S6: 1 | T6: 1 | U6: 1 | V6: 3 | W6: 1 | X6: 2 | Y6: 1 | Z6: 2 | AA6: 1 | AB6: 4 | AC6: =SUM(B6:AB6) -> 35 | AD6: =(AC6/40) -> 0.875
A7: A02 | B7: 1 | C7: 1 | D7: 1 | E7: 1 | F7: 1 | G7: 0 | H7: 2 | I7: 0 | J7: 1 | K7: 0 | L7: 0 | M7: 1 | N7: 1 | O7: 1 | P7: 1 | Q7: 0 | R7: 1 | S7: 1 | T7: 0 | U7: 0 | V7: 0 | W7: 0 | X7: 0 | Y7: 0 | Z7: 0 | AA7: 0 | AB7: 2 | AC7: =SUM(B7:AB7) -> 16 | AD7: =(AC7/40) -> 0.4
A8: A03 | B8: 1 | C8: 1 | D8: 1 | E8: 1 | F8: 0 | G8: 1 | H8: 2 | I8: 1 | J8: 1 | K8: 1 | L8: 0 | M8: 1 | N8: 1 | O8: 1 | P8: 1 | Q8: 1 | R8: 1 | S8: 1 | T8: 1 | U8: 1 | V8: 1 | W8: 1 | X8: 2 | Y8: 2 | Z8: 2 | AA8: 1 | AB8: 6 | AC8: =SUM(B8:AB8) -> 34 | AD8: =(AC8/40) -> 0.85
A9: A04 | B9: 1 | C9: 1 | D9: 1 | E9: 1 | F9: 0 | G9: 1 | H9: 2 | I9: 0 | J9: 1 | K9: 0 | L9: 1 | M9: 1 | N9: 0 | O9: 0 | P9: 1 | Q9: 0 | R9: 0 | S9: 1 | T9: 0 | U9: 0 | V9: 1 | W9: 0 | X9: 0 | Y9: 0 | Z9: 2 | AA9: 0 | AB9: 3 | AC9: =SUM(B9:AB9) -> 18 | AD9: =(AC9/40) -> 0.45
A10: A05 | B10: 1 | C10: 1 | D10: 1 | E10: 0 | F10: 0 | G10: 0 | H10: 0 | I10: 0 | J10: 1 | K10: 0 | L10: 0 | M10: 1 | N10: 1 | O10: 1 | P10: 1 | Q10: 0 | R10: 0 | S10: 1 | T10: 0 | U10: 0 | V10: 0 | W10: 0 | X10: 0 | Y10: 0 | Z10: 0 | AA10: 0 | AB10: 2 | AC10: =SUM(B10:AB10) -> 11 | AD10: =(AC10/40) -> 0.275
A11: A06 | B11: 1 | C11: 1 | D11: 1 | E11: 1 | F11: 0 | G11: 1 | H11: 1 | I11: 1 | J11: 1 | K11: 0 | L11: 1 | M11: 1 | N11: 0 | O11: 1 | P11: 1 | Q11: 0 | R11: 1 | S11: 1 | T11: 0 | U11: 0 | V11: 1 | W11: 0 | X11: 0 | Y11: 0 | Z11: 1 | AA11: 1 | AB11: 5 | AC11: =SUM(B11:AB11) -> 22 | AD11: =(AC11/40) -> 0.55
A12: A07 | B12: 1 | C12: 1 | D12: 1 | E12: 1 | F12: 0 | G12: 1 | H12: 1 | I12: 1 | J12: 1 | K12: 0 | L12: 1 | M12: 1 | N12: 1 | O12: 1 | P12: 1 | Q12: 0 | R12: 1 | S12: 0 | T12: 0 | U12: 1 | V12: 0 | W12: 0 | X12: 1 | Y12: 0 | Z12: 2 | AA12: 1 | AB12: 5 | AC12: =SUM(B12:AB12) -> 24 | AD12: =(AC12/40) -> 0.6
A13: A08 | B13: 1 | C13: 1 | D13: 1 | E13: 1 | F13: 0 | G13: 1 | H13: 1 | I13: 0 | J13: 1 | K13: 0 | L13: 0 | M13: 1 | N13: 1 | O13: 0 | P13: 1 | Q13: 1 | R13: 1 | S13: 0 | T13: 1 | U13: 1 | V13: 2 | W13: 0 | X13: 1 | Y13: 0 | Z13: 1 | AA13: 0 | AB13: 2 | AC13: =SUM(B13:AB13) -> 20 | AD13: =(AC13/40) -> 0.5
A14: A09 | B14: 1 | C14: 1 | D14: 1 | E14: 1 | F14: 0 | G14: 1 | H14: 0 | I14: 0 | J14: 1 | K14: 0 | L14: 0 | M14: 1 | N14: 1 | O14: 1 | P14: 1 | Q14: 0 | R14: 0 | S14: 1 | T14: 1 | U14: 1 | V14: 1 | W14: 0 | X14: 0 | Y14: 0 | Z14: 0 | AA14: 1 | AB14: 2 | AC14: =SUM(B14:AB14) -> 17 | AD14: =(AC14/40) -> 0.425
A15: A10 | B15: 1 | C15: 1 | D15: 1 | E15: 1 | F15: 0 | G15: 0 | H15: 0 | I15: 0 | J15: 0 | K15: 0 | L15: 0 | M15: 0 | N15: 0 | O15: 1 | P15: 0 | Q15: 0 | R15: 1 | S15: 1 | T15: 0 | U15: 1 | V15: 1 | W15: 0 | X15: 0 | Y15: 0 | Z15: 0 | AA15: 1 | AB15: 0 | AC15: =SUM(B15:AB15) -> 10 | AD15: =(AC15/40) -> 0.25
A16: A11 | B16: 1 | C16: 1 | D16: 1 | E16: 1 | F16: 0 | G16: 1 | H16: 2 | I16: 0 | J16: 1 | K16: 0 | L16: 1 | M16: 1 | N16: 1 | O16: 1 | P16: 1 | Q16: 0 | R16: 1 | S16: 1 | T16: 0 | U16: 0 | V16: 2 | W16: 0 | X16: 0 | Y16: 0 | Z16: 2 | AA16: 0 | AB16: 5 | AC16: =SUM(B16:AB16) -> 24 | AD16: =(AC16/40) -> 0.6
A17: A12 | B17: 1 | C17: 1 | D17: 1 | E17: 1 | F17: 0 | G17: 1 | H17: 2 | I17: 0 | J17: 1 | K17: 0 | L17: 1 | M17: 1 | N17: 0 | O17: 0 | P17: 1 | Q17: 0 | R17: 0 | S17: 1 | T17: 0 | U17: 1 | V17: 1 | W17: 0 | X17: 0 | Y17: 0 | Z17: 2 | AA17: 1 | AB17: 5 | AC17: =SUM(B17:AB17) -> 22 | AD17: =(AC17/40) -> 0.55
... A30: A25 | B30: 1 | C30: 1 | D30: 1 | E30: 1 | F30: 1 | G30: 1 | H30: 2 | I30: 1 | J30: 1 | K30: 0 | L30: 1 | M30: 1 | N30: 1 | O30: 1 | P30: 1 | Q30: 1 | R30: 0 | S30: 1 | T30: 0 | U30: 1 | V30: 2 | W30: 1 | X30: 2 | Y30: 2 | Z30: 2 | AA30: 0 | AB30: 4 | AC30: =SUM(B30:AB30) -> 31 | AD30: =(AC30/40) -> 0.775
A35: suma | B35: =SUM(B6:B30) -> 25 | C35: =SUM(C6:C30) -> 25 | D35: =SUM(D6:D30) -> 23 | E35: =SUM(E6:E30) -> 22 | F35: =SUM(F6:F30) -> 4 | G35: =SUM(G6:G30) -> 21 | H35: =SUM(H6:H30) -> 29 | I35: =SUM(I6:I30) -> 11 | ... AB35: =SUM(AB6:AB30) -> 92
A36: średnia | B36: =AVERAGE(B6:B30) -> 1 | C36: =AVERAGE(C6:C30) -> 1 | D36: =AVERAGE(D6:D30) -> 0.92 | E36: =AVERAGE(E6:E30) -> 0.88 | F36: =AVERAGE(F6:F30) -> 0.16 | G36: =AVERAGE(G6:G30) -> 0.84 | H36: =AVERAGE(H6:H30) -> 1.16 | I36: =AVERAGE(I6:I30) -> 0.44 | ... AB36: =AVERAGE(AB6:AB30) -> 3.68
A37: wsółczynnik łatwości zadania | B37: =B35/(B5*$C$1) -> 1 | C37: =C35/(C5*$C$1) -> 1 | D37: =D35/(D5*$C$1) -> 0.92 | E37: =E35/(E5*$C$1) -> 0.88 | F37: =F35/(F5*$C$1) -> 0.16 | G37: =G35/(G5*$C$1) -> 0.84 | H37: =H35/(H5*$C$1) -> 0.58 | I37: =I35/(I5*$C$1) -> 0.44 | ... AB37: =AB35/(AB5*$C$1) -> 0.46
A38: poziom trudnosci zadania | B38: {=_xlfn.IFS(B37>=0.9,"bardzo łatwe",B37>=0.7,"łatwe",B37>=0.5,"umierkowanie trudne",B37>=0.2,"trudne",B37,"bardzo trudne")} -> bardzo łatwe | C38: {=_xlfn.IFS(C37>=0.9,"bardzo łatwe",C37>=0.7,"łatwe",C37>=0.5,"umierkowanie trudne",C37>=0.2,"trudne",C37,"bardzo trudne")} -> bardzo łatwe | D38: {=_xlfn.IFS(D37>=0.9,"bardzo łatwe",D37>=0.7,"łatwe",D37>=0.5,"umierkowanie trudne",D37>=0.2,"trudne",D37,"bardzo trudne")} -> bardzo łatwe | E38: {=_xlfn.IFS(E37>=0.9,"bardzo łatwe",E37>=0.7,"łatwe",E37>=0.5,"umierkowanie trudne",E37>=0.2,"trudne",E37,"bardzo trudne")} -> łatwe | F38: {=_xlfn.IFS(F37>=0.9,"bardzo łatwe",F37>=0.7,"łatwe",F37>=0.5,"umierkowanie trudne",F37>=0.2,"trudne",F37,"bardzo trudne")} -> bardzo trudne | G38: {=_xlfn.IFS(G37>=0.9,"bardzo łatwe",G37>=0.7,"łatwe",G37>=0.5,"umierkowanie trudne",G37>=0.2,"trudne",G37,"bardzo trudne")} -> łatwe | H38: {=_xlfn.IFS(H37>=0.9,"bardzo łatwe",H37>=0.7,"łatwe",H37>=0.5,"umierkowanie trudne",H37>=0.2,"trudne",H37,"bardzo trudne")} -> umierkowanie trudne | I38: {=_xlfn.IFS(I37>=0.9,"bardzo łatwe",I37>=0.7,"łatwe",I37>=0.5,"umierkowanie trudne",I37>=0.2,"trudne",I37,"bardzo trudne")} -> trudne | ... AB38: {=_xlfn.IFS(AB37>=0.9,"bardzo łatwe",AB37>=0.7,"łatwe",AB37>=0.5,"umierkowanie trudne",AB37>=0.2,"trudne",AB37,"bardzo trudne")} -> trudne
B45: Max w standardach | G45: liczba punktów w standardach w klasia A | L45: Współczynnik łatwości standardów
A46: oddz | B46: I | C46: II | D46: III | E46: IV | F46: V | G46: =B46 -> I | H46: =C46 -> II | I46: =D46 -> III | J46: =E46 -> IV | K46: =F46 -> V | L46: =B46 -> I | M46: =C46 -> II | N46: =D46 -> III | O46: =E46 -> IV | P46: =F46 -> V
A47: A | B47: =$C$1*SUMIFS($B$5:$AB$5,$B$4:$AB$4,B46) -> 250 | C47: =$C$1*SUMIFS($B$5:$AB$5,$B$4:$AB$4,C46) -> 200 | D47: =$C$1*SUMIFS($B$5:$AB$5,$B$4:$AB$4,D46) -> 225 | E47: =$C$1*SUMIFS($B$5:$AB$5,$B$4:$AB$4,E46) -> 100 | F47: =$C$1*SUMIFS($B$5:$AB$5,$B$4:$AB$4,F46) -> 225 | G47: =SUMIFS($B$35:$AB$35,$B$4:$AB$4,G46) -> 192 | H47: =SUMIFS($B$35:$AB$35,$B$4:$AB$4,H46) -> 92 | I47: =SUMIFS($B$35:$AB$35,$B$4:$AB$4,I46) -> 84 | J47: =SUMIFS($B$35:$AB$35,$B$4:$AB$4,J46) -> 62 | K47: =SUMIFS($B$35:$AB$35,$B$4:$AB$4,K46) -> 105 | L47: =G47/(B47) -> 0.768 | M47: =H47/(C47) -> 0.46 | N47: =I47/(D47) -> 0.37333333 | O47: =J47/(E47) -> 0.62 | P47: =K47/(F47) -> 0.46666667
B50: Wskaźniki egzaminu
B52: Liczba piszących | F52: =COUNTA(A6:A30) -> 25
B53: Łatwość zestawu | F53: =SUM(B35:AB35)/(SUM(B5:AB5)*C1) -> 0.535
B54: Średni wynik | F54: =AVERAGE(AC6:AC30) -> 21.4
B55: Mediana | F55: =MEDIAN(AC6:AC30) -> 22
B56: Modalna | F56: =_xlfn.MODE.SNGL(AC6:AC30) -> 22
B57: Wynik maksymalny | F57: =MAX(AC6:AC30) -> 35
B58: Wynik minimalny | F58: =MIN(AC6:AC30) -> 10
B59: Rozstęp wyników | F59: =F57-F58 -> 25
B60: Odchylenie standardowe | F60: =_xlfn.STDEV.S(AC6:AC30) -> 6.9641941

Sheet KLASA B
A1: KLASA B | B1: liczba uczniów | C1: 26
A3: Zadanie | B3: 1 | C3: 2 | D3: 3 | E3: 4 | F3: 5 | G3: 6 | H3: 7 | I3: 8 | J3: 9 | K3: 10 | L3: 11 | M3: 12 | N3: 13 | O3: 14 | P3: 15 | Q3: 16 | R3: 17 | S3: 18 | T3: 19 | U3: 20 | V3: 21 I | W3: 21 II | X3: 22 I | Y3: 22 II | Z3: 23 | AA3: 24 | AB3: 25
A4: Standard | B4: I | C4: I | D4: I | E4: I | F4: III | G4: IV | H4: IV | I4: V | J4: V | K4: III | L4: III | M4: V | N4: V | O4: I | P4: I | Q4: I | R4: IV | S4: III | T4: V | U4: V | V4: III | W4: V | X4: III | Y4: V | Z4: I | AA4: I | AB4: II
A5: Max liczba punktów | B5: 1 | C5: 1 | D5: 1 | E5: 1 | F5: 1 | G5: 1 | H5: 2 | I5: 1 | J5: 1 | K5: 1 | L5: 1 | M5: 1 | N5: 1 | O5: 1 | P5: 1 | Q5: 1 | R5: 1 | S5: 1 | T5: 1 | U5: 1 | V5: 3 | W5: 1 | X5: 2 | Y5: 2 | Z5: 2 | AA5: 1 | AB5: 8 | AC5: suma | AD5: procent
A6: B01 | B6: 1 | C6: 1 | D6: 1 | E6: 0 | F6: 1 | G6: 1 | H6: 2 | I6: 0 | J6: 1 | K6: 0 | L6: 0 | M6: 1 | N6: 1 | O6: 1 | P6: 1 | Q6: 0 | R6: 0 | S6: 0 | T6: 1 | U6: 1 | V6: 0 | W6: 0 | X6: 0 | Y6: 0 | Z6: 0 | AA6: 0 | AB6: 0 | AC6: =SUM(B6:AB6) -> 14 | AD6: =AC6/40 -> 0.35
A7: B02 | B7: 1 | C7: 0 | D7: 1 | E7: 1 | F7: 0 | G7: 1 | H7: 0 | I7: 0 | J7: 1 | K7: 1 | L7: 1 | M7: 1 | N7: 1 | O7: 1 | P7: 1 | Q7: 0 | R7: 0 | S7: 1 | T7: 0 | U7: 0 | V7: 0 | W7: 0 | X7: 1 | Y7: 0 | Z7: 1 | AA7: 1 | AB7: 4 | AC7: =SUM(B7:AB7) -> 19 | AD7: =AC7/40 -> 0.475
A8: B03 | B8: 1 | C8: 1 | D8: 1 | E8: 0 | F8: 1 | G8: 1 | H8: 0 | I8: 0 | J8: 1 | K8: 0 | L8: 0 | M8: 1 | N8: 1 | O8: 1 | P8: 0 | Q8: 0 | R8: 0 | S8: 0 | T8: 0 | U8: 0 | V8: 0 | W8: 0 | X8: 0 | Y8: 0 | Z8: 2 | AA8: 0 | AB8: 3 | AC8: =SUM(B8:AB8) -> 14 | AD8: =AC8/40 -> 0.35
A9: B04 | B9: 1 | C9: 1 | D9: 1 | E9: 1 | F9: 0 | G9: 1 | H9: 2 | I9: 0 | J9: 1 | K9: 0 | L9: 1 | M9: 1 | N9: 1 | O9: 1 | P9: 1 | Q9: 0 | R9: 1 | S9: 1 | T9: 1 | U9: 0 | V9: 1 | W9: 0 | X9: 1 | Y9: 0 | Z9: 2 | AA9: 1 | AB9: 0 | AC9: =SUM(B9:AB9) -> 21 | AD9: =AC9/40 -> 0.525
A10: B05 | B10: 1 | C10: 1 | D10: 1 | E10: 1 | F10: 1 | G10: 1 | H10: 2 | I10: 1 | J10: 1 | K10: 0 | L10: 1 | M10: 1 | N10: 1 | O10: 1 | P10: 1 | Q10: 1 | R10: 1 | S10: 1 | T10: 0 | U10: 1 | V10: 1 | W10: 0 | X10: 0 | Y10: 0 | Z10: 2 | AA10: 1 | AB10: 3 | AC10: =SUM(B10:AB10) -> 26 | AD10: =AC10/40 -> 0.65
A11: B06 | B11: 1 | C11: 1 | D11: 1 | E11: 1 | F11: 1 | G11: 1 | H11: 2 | I11: 0 | J11: 1 | K11: 1 | L11: 1 | M11: 1 | N11: 1 | O11: 1 | P11: 1 | Q11: 1 | R11: 1 | S11: 1 | T11: 1 | U11: 1 | V11: 2 | W11: 1 | X11: 1 | Y11: 0 | Z11: 1 | AA11: 1 | AB11: 5 | AC11: =SUM(B11:AB11) -> 31 | AD11: =AC11/40 -> 0.775
A12: B07 | B12: 1 | C12: 0 | D12: 0 | E12: 1 | F12: 1 | G12: 1 | H12: 2 | I12: 0 | J12: 1 | K12: 1 | L12: 0 | M12: 1 | N12: 0 | O12: 1 | P12: 1 | Q12: 0 | R12: 0 | S12: 1 | T12: 0 | U12: 0 | V12: 0 | W12: 0 | X12: 0 | Y12: 0 | Z12: 2 | AA12: 0 | AB12: 0 | AC12: =SUM(B12:AB12) -> 14 | AD12: =AC12/40 -> 0.35
A13: B08 | B13: 1 | C13: 1 | D13: 1 | E13: 1 | F13: 1 | G13: 1 | H13: 0 | I13: 0 | J13: 1 | K13: 1 | L13: 1 | M13: 1 | N13: 1 | O13: 0 | P13: 1 | Q13: 0 | R13: 1 | S13: 1 | T13: 0 | U13: 0 | V13: 1 | W13: 0 | X13: 0 | Y13: 0 | Z13: 2 | AA13: 0 | AB13: 5 | AC13: =SUM(B13:AB13) -> 22 | AD13: =AC13/40 -> 0.55
A14: B09 | B14: 1 | C14: 1 | D14: 1 | E14: 0 | F14: 0 | G14: 1 | H14: 2 | I14: 1 | J14: 1 | K14: 0 | L14: 1 | M14: 1 | N14: 1 | O14: 1 | P14: 1 | Q14: 0 | R14: 1 | S14: 1 | T14: 0 | U14: 0 | V14: 0 | W14: 0 | X14: 0 | Y14: 0 | Z14: 2 | AA14: 0 | AB14: 5 | AC14: =SUM(B14:AB14) -> 22 | AD14: =AC14/40 -> 0.55
A15: B10 | B15: 1 | C15: 0 | D15: 0 | E15: 0 | F15: 1 | G15: 1 | H15: 1 | I15: 1 | J15: 0 | K15: 0 | L15: 0 | M15: 0 | N15: 0 | O15: 0 | P15: 0 | Q15: 0 | R15: 0 | S15: 0 | T15: 1 | U15: 1 | V15: 1 | W15: 0 | X15: 0 | Y15: 0 | Z15: 1 | AA15: 1 | AB15: 0 | AC15: =SUM(B15:AB15) -> 10 | AD15: =AC15/40 -> 0.25
A16: B11 | B16: 1 | C16: 1 | D16: 1 | E16: 1 | F16: 0 | G16: 1 | H16: 2 | I16: 1 | J16: 1 | K16: 0 | L16: 1 | M16: 1 | N16: 1 | O16: 1 | P16: 1 | Q16: 1 | R16: 1 | S16: 1 | T16: 0 | U16: 1 | V16: 1 | W16: 0 | X16: 0 | Y16: 0 | Z16: 2 | AA16: 1 | AB16: 5 | AC16: =SUM(B16:AB16) -> 27 | AD16: =AC16/40 -> 0.675
A17: B12 | B17: 1 | C17: 1 | D17: 1 | E17: 0 | F17: 0 | G17: 1 | H17: 0 | I17: 1 | J17: 1 | K17: 1 | L17: 1 | M17: 1 | N17: 1 | O17: 1 | P17: 1 | Q17: 0 | R17: 1 | S17: 1 | T17: 0 | U17: 1 | V17: 3 | W17: 1 | X17: 0 | Y17: 0 | Z17: 2 | AA17: 0 | AB17: 2 | AC17: =SUM(B17:AB17) -> 23 | AD17: =AC17/40 -> 0.575
... A31: B26 | B31: 1 | C31: 1 | D31: 1 | E31: 0 | F31: 0 | G31: 1 | H31: 0 | I31: 0 | J31: 0 | K31: 1 | L31: 0 | M31: 1 | N31: 1 | O31: 1 | P31: 1 | Q31: 0 | R31: 1 | S31: 1 | T31: 1 | U31: 1 | V31: 0 | W31: 0 | X31: 0 | Y31: 0 | Z31: 0 | AA31: 1 | AB31: 2 | AC31: =SUM(B31:AB31) -> 16 | AD31: =AC31/40 -> 0.4
A35: suma | B35: =SUM(B6:B31) -> 26 | C35: =SUM(C6:C31) -> 21 | D35: =SUM(D6:D31) -> 24 | E35: =SUM(E6:E31) -> 14 | F35: =SUM(F6:F31) -> 12 | G35: =SUM(G6:G31) -> 25 | H35: =SUM(H6:H31) -> 37 | I35: =SUM(I6:I31) -> 8 | ... AB35: =SUM(AB6:AB31) -> 78
A36: średnia | B36: =AVERAGE(B6:B31) -> 1 | C36: =AVERAGE(C6:C31) -> 0.80769231 | D36: =AVERAGE(D6:D31) -> 0.92307692 | E36: =AVERAGE(E6:E31) -> 0.53846154 | F36: =AVERAGE(F6:F31) -> 0.46153846 | G36: =AVERAGE(G6:G31) -> 0.96153846 | H36: =AVERAGE(H6:H31) -> 1.4230769 | I36: =AVERAGE(I6:I31) -> 0.30769231 | ... AB36: =AVERAGE(AB6:AB31) -> 3
A37: wsółczynnik łatwości zadania | B37: =B35/(B5*$C$1) -> 1 | C37: =C35/(C5*$C$1) -> 0.80769231 | D37: =D35/(D5*$C$1) -> 0.92307692 | E37: =E35/(E5*$C$1) -> 0.53846154 | F37: =F35/(F5*$C$1) -> 0.46153846 | G37: =G35/(G5*$C$1) -> 0.96153846 | H37: =H35/(H5*$C$1) -> 0.71153846 | I37: =I35/(I5*$C$1) -> 0.30769231 | ... AB37: =AB35/(AB5*$C$1) -> 0.375
A38: poziom trudnosci zadania | B38: {=_xlfn.IFS(B37>=0.9,"bardzo łatwe",B37>=0.7,"łatwe",B37>=0.5,"umierkowanie trudne",B37>=0.2,"trudne",B37,"bardzo trudne")} -> bardzo łatwe | C38: {=_xlfn.IFS(C37>=0.9,"bardzo łatwe",C37>=0.7,"łatwe",C37>=0.5,"umierkowanie trudne",C37>=0.2,"trudne",C37,"bardzo trudne")} -> łatwe | D38: {=_xlfn.IFS(D37>=0.9,"bardzo łatwe",D37>=0.7,"łatwe",D37>=0.5,"umierkowanie trudne",D37>=0.2,"trudne",D37,"bardzo trudne")} -> bardzo łatwe | E38: {=_xlfn.IFS(E37>=0.9,"bardzo łatwe",E37>=0.7,"łatwe",E37>=0.5,"umierkowanie trudne",E37>=0.2,"trudne",E37,"bardzo trudne")} -> umierkowanie trudne | F38: {=_xlfn.IFS(F37>=0.9,"bardzo łatwe",F37>=0.7,"łatwe",F37>=0.5,"umierkowanie trudne",F37>=0.2,"trudne",F37,"bardzo trudne")} -> trudne | G38: {=_xlfn.IFS(G37>=0.9,"bardzo łatwe",G37>=0.7,"łatwe",G37>=0.5,"umierkowanie trudne",G37>=0.2,"trudne",G37,"bardzo trudne")} -> bardzo łatwe | H38: {=_xlfn.IFS(H37>=0.9,"bardzo łatwe",H37>=0.7,"łatwe",H37>=0.5,"umierkowanie trudne",H37>=0.2,"trudne",H37,"bardzo trudne")} -> łatwe | I38: {=_xlfn.IFS(I37>=0.9,"bardzo łatwe",I37>=0.7,"łatwe",I37>=0.5,"umierkowanie trudne",I37>=0.2,"trudne",I37,"bardzo trudne")} -> trudne | ... AB38: {=_xlfn.IFS(AB37>=0.9,"bardzo łatwe",AB37>=0.7,"łatwe",AB37>=0.5,"umierkowanie trudne",AB37>=0.2,"trudne",AB37,"bardzo trudne")} -> trudne
B45: Max w standardach | G45: liczba punktów w standardach w klasia A | L45: Współczynnik łatwości standardów
A46: oddz | B46: I | C46: II | D46: III | E46: IV | F46: V | G46: =B46 -> I | H46: =C46 -> II | I46: =D46 -> III | J46: =E46 -> IV | K46: =F46 -> V | L46: =B46 -> I | M46: =C46 -> II | N46: =D46 -> III | O46: =E46 -> IV | P46: =F46 -> V
A47: A | B47: =$C$1*SUMIFS($B$5:$AB$5,B$4:AB$4,B46) -> 260 | C47: =$C$1*SUMIFS($B$5:$AB$5,C$4:AC$4,C46) -> 26 | D47: =$C$1*SUMIFS($B$5:$AB$5,D$4:AD$4,D46) -> 208 | E47: =$C$1*SUMIFS($B$5:$AB$5,E$4:AE$4,E46) -> 78 | F47: =$C$1*SUMIFS($B$5:$AB$5,F$4:AF$4,F46) -> 208 | G47: =SUMIFS($B$35:$AB$35,$B$4:$AB$4,G46) -> 200 | H47: =SUMIFS($B$35:$AB$35,$B$4:$AB$4,H46) -> 78 | I47: =SUMIFS($B$35:$AB$35,$B$4:$AB$4,I46) -> 97 | J47: =SUMIFS($B$35:$AB$35,$B$4:$AB$4,J46) -> 81 | K47: =SUMIFS($B$35:$AB$35,$B$4:$AB$4,K46) -> 110 | L47: =B47/G47 -> 1.3 | M47: =C47/H47 -> 0.33333333 | N47: =D47/I47 -> 2.1443299 | O47: =E47/J47 -> 0.96296296 | P47: =F47/K47 -> 1.8909091
B50: Wskaźniki egzaminu
B52: Liczba piszących | F52: =COUNTA(A6:A31) -> 26
B53: Łatwość zestawu
B54: Średni wynik | F54: =AVERAGE(AC6:AC31) -> 21.769231
B55: Mediana | F55: =MEDIAN(AC6:AC31) -> 22.5
B56: Modalna | F56: =_xlfn.MODE.SNGL(AC6:AC31) -> 14
B57: Wynik maksymalny
B58: Wynik minimalny
B59: Rozstęp wyników
B60: Odchylenie standardowe

Sheet KLASA C
A1: KLASA C | B1: liczba uczniów | C1: 27
A3: Zadanie | B3: 1 | C3: 2 | D3: 3 | E3: 4 | F3: 5 | G3: 6 | H3: 7 | I3: 8 | J3: 9 | K3: 10 | L3: 11 | M3: 12 | N3: 13 | O3: 14 | P3: 15 | Q3: 16 | R3: 17 | S3: 18 | T3: 19 | U3: 20 | V3: 21 I | W3: 21 II | X3: 22 I | Y3: 22 II | Z3: 23 | AA3: 24 | AB3: 25
A4: Standard | B4: I | C4: I | D4: I | E4: I | F4: III | G4: IV | H4: IV | I4: V | J4: V | K4: III | L4: III | M4: V | N4: V | O4: I | P4: I | Q4: I | R4: IV | S4: III | T4: V | U4: V | V4: III | W4: V | X4: III | Y4: V | Z4: I | AA4: I | AB4: II
A5: Max liczba punktów | B5: 1 | C5: 1 | D5: 1 | E5: 1 | F5: 1 | G5: 1 | H5: 2 | I5: 1 | J5: 1 | K5: 1 | L5: 1 | M5: 1 | N5: 1 | O5: 1 | P5: 1 | Q5: 1 | R5: 1 | S5: 1 | T5: 1 | U5: 1 | V5: 3 | W5: 1 | X5: 2 | Y5: 2 | Z5: 2 | AA5: 1 | AB5: 8 | AC5: suma | AD5: średnia
A6: C01 | B6: 1 | C6: 1 | D6: 1 | E6: 1 | F6: 0 | G6: 0 | H6: 2 | I6: 1 | J6: 1 | K6: 1 | L6: 1 | M6: 1 | N6: 1 | O6: 0 | P6: 1 | Q6: 0 | R6: 1 | S6: 1 | T6: 1 | U6: 1 | V6: 3 | W6: 1 | X6: 2 | Y6: 2 | Z6: 2 | AA6: 0 | AB6: 3
A7: C02 | B7: 1 | C7: 0 | D7: 1 | E7: 1 | F7: 0 | G7: 1 | H7: 2 | I7: 1 | J7: 1 | K7: 0 | L7: 0 | M7: 0 | N7: 1 | O7: 0 | P7: 0 | Q7: 0 | R7: 1 | S7: 1 | T7: 1 | U7: 1 | V7: 1 | W7: 0 | X7: 0 | Y7: 0 | Z7: 2 | AA7: 1 | AB7: 0
A8: C03 | B8: 1 | C8: 1 | D8: 1 | E8: 1 | F8: 0 | G8: 1 | H8: 2 | I8: 0 | J8: 0 | K8: 0 | L8: 1 | M8: 1 | N8: 0 | O8: 1 | P8: 1 | Q8: 0 | R8: 0 | S8: 1 | T8: 0 | U8: 0 | V8: 2 | W8: 0 | X8: 0 | Y8: 0 | Z8: 0 | AA8: 1 | AB8: 2
A9: C04 | B9: 1 | C9: 1 | D9: 1 | E9: 1 | F9: 0 | G9: 1 | H9: 2 | I9: 1 | J9: 1 | K9: 0 | L9: 1 | M9: 1 | N9: 1 | O9: 1 | P9: 1 | Q9: 1 | R9: 1 | S9: 1 | T9: 1 | U9: 0 | V9: 1 | W9: 0 | X9: 0 | Y9: 0 | Z9: 1 | AA9: 0 | AB9: 5
A10: C05 | B10: 1 | C10: 1 | D10: 1 | E10: 1 | F10: 1 | G10: 1 | H10: 2 | I10: 0 | J10: 0 | K10: 0 | L10: 1 | M10: 1 | N10: 1 | O10: 0 | P10: 1 | Q10: 0 | R10: 1 | S10: 0 | T10: 0 | U10: 0 | V10: 0 | W10: 0 | X10: 0 | Y10: 0 | Z10: 2 | AA10: 0 | AB10: 0
A11: C06 | B11: 1 | C11: 1 | D11: 1 | E11: 1 | F11: 0 | G11: 1 | H11: 2 | I11: 0 | J11: 1 | K11: 1 | L11: 1 | M11: 1 | N11: 1 | O11: 1 | P11: 1 | Q11: 0 | R11: 1 | S11: 1 | T11: 1 | U11: 1 | V11: 3 | W11: 0 | X11: 2 | Y11: 0 | Z11: 2 | AA11: 1 | AB11: 5
A12: C07 | B12: 1 | C12: 0 | D12: 1 | E12: 1 | F12: 0 | G12: 1 | H12: 0 | I12: 0 | J12: 1 | K12: 0 | L12: 1 | M12: 1 | N12: 0 | O12: 1 | P12: 1 | Q12: 0 | R12: 0 | S12: 0 | T12: 0 | U12: 0 | V12: 0 | W12: 0 | X12: 0 | Y12: 0 | Z12: 2 | AA12: 0 | AB12: 3
A13: C08 | B13: 1 | C13: 1 | D13: 1 | E13: 0 | F13: 0 | G13: 1 | H13: 2 | I13: 1 | J13: 1 | K13: 1 | L13: 1 | M13: 1 | N13: 1 | O13: 1 | P13: 1 | Q13: 1 | R13: 1 | S13: 1 | T13: 1 | U13: 1 | V13: 3 | W13: 1 | X13: 2 | Y13: 0 | Z13: 2 | AA13: 1 | AB13: 5
A14: C09 | B14: 1 | C14: 1 | D14: 1 | E14: 1 | F14: 0 | G14: 1 | H14: 1 | I14: 1 | J14: 1 | K14: 0 | L14: 0 | M14: 1 | N14: 0 | O14: 1 | P14: 1 | Q14: 0 | R14: 1 | S14: 0 | T14: 0 | U14: 1 | V14: 1 | W14: 0 | X14: 0 | Y14: 0 | Z14: 2 | AA14: 1 | AB14: 5
A15: C10 | B15: 1 | C15: 1 | D15: 1 | E15: 1 | F15: 1 | G15: 1 | H15: 2 | I15: 1 | J15: 1 | K15: 1 | L15: 1 | M15: 1 | N15: 1 | O15: 1 | P15: 1 | Q15: 0 | R15: 1 | S15: 1 | T15: 1 | U15: 0 | V15: 3 | W15: 1 | X15: 2 | Y15: 2 | Z15: 2 | AA15: 1 | AB15: 7
A16: C11 | B16: 1 | C16: 1 | D16: 0 | E16: 1 | F16: 0 | G16: 1 | H16: 2 | I16: 0 | J16: 0 | K16: 1 | L16: 1 | M16: 1 | N16: 1 | O16: 1 | P16: 1 | Q16: 1 | R16: 0 | S16: 1 | T16: 0 | U16: 0 | V16: 0 | W16: 0 | X16: 1 | Y16: 0 | Z16: 2 | AA16: 0 | AB16: 2
A17: C12 | B17: 1 | C17: 0 | D17: 1 | E17: 1 | F17: 0 | G17: 1 | H17: 2 | I17: 1 | J17: 0 | K17: 0 | L17: 1 | M17: 1 | N17: 0 | O17: 1 | P17: 1 | Q17: 0 | R17: 1 | S17: 1 | T17: 0 | U17: 0 | V17: 0 | W17: 0 | X17: 0 | Y17: 0 | Z17: 2 | AA17: 1 | AB17: 1
... A32: C27 | B32: 1 | C32: 1 | D32: 1 | E32: 0 | F32: 1 | G32: 1 | H32: 2 | I32: 1 | J32: 1 | K32: 1 | L32: 1 | M32: 1 | N32: 1 | O32: 1 | P32: 1 | Q32: 0 | R32: 1 | S32: 1 | T32: 1 | U32: 0 | V32: 3 | W32: 1 | X32: 1 | Y32: 0 | Z32: 2 | AA32: 0 | AB32: 3
A35: suma
A36: średnia
A37: wsółczynnik łatwości zadania
A38: poziom trudnosci zadania
B45: Max w standardach | G45: liczba punktów w standardach w klasia A | L45: Współczynnik łatwości standardów
A46: oddz | B46: I | C46: II | D46: III | E46: IV | F46: V | G46: =B46 -> I | H46: =C46 -> II | I46: =D46 -> III | J46: =E46 -> IV | K46: =F46 -> V | L46: =B46 -> I | M46: =C46 -> II | N46: =D46 -> III | O46: =E46 -> IV | P46: =F46 -> V
A47: A
B50: Wskaźniki egzaminu
B52: Liczba piszących
B53: Łatwość zestawu
B54: Średni wynik
B55: Mediana
B56: Modalna
B57: Wynik maksymalny
B58: Wynik minimalny
B59: Rozstęp wyników
B60: Odchylenie standardowe

Sheet KLASA D
A1: KLASA D | B1: liczba uczniów | C1: 25
A3: Zadanie | B3: 1 | C3: 2 | D3: 3 | E3: 4 | F3: 5 | G3: 6 | H3: 7 | I3: 8 | J3: 9 | K3: 10 | L3: 11 | M3: 12 | N3: 13 | O3: 14 | P3: 15 | Q3: 16 | R3: 17 | S3: 18 | T3: 19 | U3: 20 | V3: 21 I | W3: 21 II | X3: 22 I | Y3: 22 II | Z3: 23 | AA3: 24 | AB3: 25
A4: Standard | B4: I | C4: I | D4: I | E4: I | F4: III | G4: IV | H4: IV | I4: V | J4: V | K4: III | L4: III | M4: V | N4: V | O4: I | P4: I | Q4: I | R4: IV | S4: III | T4: V | U4: V | V4: III | W4: V | X4: III | Y4: V | Z4: I | AA4: I | AB4: II
A5: Max liczba punktów | B5: 1 | C5: 1 | D5: 1 | E5: 1 | F5: 1 | G5: 1 | H5: 2 | I5: 1 | J5: 1 | K5: 1 | L5: 1 | M5: 1 | N5: 1 | O5: 1 | P5: 1 | Q5: 1 | R5: 1 | S5: 1 | T5: 1 | U5: 1 | V5: 3 | W5: 1 | X5: 2 | Y5: 2 | Z5: 2 | AA5: 1 | AB5: 8 | AC5: suma | AD5: średnia
A6: D01 | B6: 1 | C6: 1 | D6: 1 | E6: 1 | F6: 1 | G6: 1 | H6: 2 | I6: 1 | J6: 1 | K6: 0 | L6: 0 | M6: 1 | N6: 1 | O6: 1 | P6: 1 | Q6: 1 | R6: 0 | S6: 1 | T6: 1 | U6: 0 | V6: 0 | W6: 0 | X6: 0 | Y6: 0 | Z6: 2 | AA6: 1 | AB6: 3
A7: D02 | B7: 1 | C7: 1 | D7: 0 | E7: 1 | F7: 0 | G7: 1 | H7: 1 | I7: 1 | J7: 1 | K7: 0 | L7: 1 | M7: 1 | N7: 1 | O7: 0 | P7: 1 | Q7: 0 | R7: 0 | S7: 1 | T7: 0 | U7: 1 | V7: 2 | W7: 0 | X7: 1 | Y7: 0 | Z7: 2 | AA7: 1 | AB7: 4
A8: D03 | B8: 1 | C8: 0 | D8: 1 | E8: 0 | F8: 1 | G8: 1 | H8: 2 | I8: 0 | J8: 1 | K8: 0 | L8: 1 | M8: 1 | N8: 1 | O8: 1 | P8: 1 | Q8: 1 | R8: 0 | S8: 1 | T8: 0 | U8: 0 | V8: 0 | W8: 0 | X8: 0 | Y8: 0 | Z8: 0 | AA8: 0 | AB8: 5
A9: D04 | B9: 1 | C9: 1 | D9: 1 | E9: 0 | F9: 0 | G9: 1 | H9: 0 | I9: 1 | J9: 1 | K9: 0 | L9: 1 | M9: 1 | N9: 1 | O9: 0 | P9: 1 | Q9: 0 | R9: 1 | S9: 0 | T9: 1 | U9: 1 | V9: 2 | W9: 1 | X9: 0 | Y9: 0 | Z9: 2 | AA9: 1 | AB9: 0
A10: D05 | B10: 1 | C10: 1 | D10: 1 | E10: 1 | F10: 0 | G10: 1 | H10: 2 | I10: 0 | J10: 1 | K10: 1 | L10: 1 | M10: 1 | N10: 1 | O10: 1 | P10: 1 | Q10: 1 | R10: 1 | S10: 1 | T10: 1 | U10: 1 | V10: 0 | W10: 0 | X10: 2 | Y10: 2 | Z10: 2 | AA10: 1 | AB10: 4
A11: D06 | B11: 1 | C11: 0 | D11: 1 | E11: 1 | F11: 0 | G11: 1 | H11: 0 | I11: 0 | J11: 1 | K11: 0 | L11: 0 | M11: 1 | N11: 0 | O11: 1 | P11: 1 | Q11: 0 | R11: 1 | S11: 1 | T11: 0 | U11: 0 | V11: 2 | W11: 0 | X11: 0 | Y11: 0 | Z11: 2 | AA11: 0 | AB11: 1
A12: D07 | B12: 1 | C12: 1 | D12: 1 | E12: 0 | F12: 1 | G12: 1 | H12: 2 | I12: 1 | J12: 1 | K12: 1 | L12: 1 | M12: 1 | N12: 1 | O12: 1 | P12: 1 | Q12: 1 | R12: 1 | S12: 1 | T12: 1 | U12: 1 | V12: 3 | W12: 1 | X12: 2 | Y12: 2 | Z12: 2 | AA12: 1 | AB12: 6
A13: D08 | B13: 1 | C13: 1 | D13: 1 | E13: 1 | F13: 0 | G13: 1 | H13: 0 | I13: 1 | J13: 1 | K13: 0 | L13: 1 | M13: 1 | N13: 1 | O13: 1 | P13: 1 | Q13: 1 | R13: 1 | S13: 0 | T13: 0 | U13: 0 | V13: 0 | W13: 0 | X13: 1 | Y13: 0 | Z13: 2 | AA13: 1 | AB13: 1
A14: D09 | B14: 1 | C14: 1 | D14: 1 | E14: 1 | F14: 0 | G14: 1 | H14: 2 | I14: 1 | J14: 1 | K14: 1 | L14: 1 | M14: 1 | N14: 1 | O14: 1 | P14: 1 | Q14: 1 | R14: 1 | S14: 1 | T14: 1 | U14: 0 | V14: 3 | W14: 1 | X14: 0 | Y14: 0 | Z14: 2 | AA14: 1 | AB14: 6
A15: D10 | B15: 1 | C15: 1 | D15: 1 | E15: 1 | F15: 1 | G15: 1 | H15: 2 | I15: 1 | J15: 1 | K15: 1 | L15: 1 | M15: 1 | N15: 1 | O15: 1 | P15: 1 | Q15: 1 | R15: 1 | S15: 1 | T15: 1 | U15: 1 | V15: 3 | W15: 0 | X15: 2 | Y15: 2 | Z15: 2 | AA15: 1 | AB15: 5
A16: D11 | B16: 0 | C16: 1 | D16: 1 | E16: 1 | F16: 0 | G16: 1 | H16: 2 | I16: 1 | J16: 1 | K16: 1 | L16: 1 | M16: 1 | N16: 1 | O16: 1 | P16: 1 | Q16: 1 | R16: 1 | S16: 1 | T16: 0 | U16: 1 | V16: 3 | W16: 1 | X16: 2 | Y16: 2 | Z16: 2 | AA16: 1 | AB16: 5
A17: D12 | B17: 1 | C17: 1 | D17: 1 | E17: 1 | F17: 0 | G17: 1 | H17: 0 | I17: 1 | J17: 1 | K17: 0 | L17: 1 | M17: 1 | N17: 1 | O17: 1 | P17: 1 | Q17: 1 | R17: 0 | S17: 1 | T17: 0 | U17: 0 | V17: 3 | W17: 0 | X17: 1 | Y17: 0 | Z17: 1 | AA17: 0 | AB17: 5
... A30: D25 | B30: 1 | C30: 1 | D30: 1 | E30: 1 | F30: 1 | G30: 1 | H30: 2 | I30: 1 | J30: 1 | K30: 0 | L30: 1 | M30: 1 | N30: 1 | O30: 1 | P30: 1 | Q30: 0 | R30: 1 | S30: 1 | T30: 1 | U30: 0 | V30: 3 | W30: 0 | X30: 1 | Y30: 0 | Z30: 2 | AA30: 1 | AB30: 7
A35: suma
A36: średnia
A37: wsółczynnik łatwości zadania
A38: poziom trudnosci zadania
B45: Max w standardach | G45: liczba punktów w standardach w klasia A | L45: Współczynnik łatwości standardów
A46: oddz | B46: I | C46: II | D46: III | E46: IV | F46: V | G46: =B46 -> I | H46: =C46 -> II | I46: =D46 -> III | J46: =E46 -> IV | K46: =F46 -> V | L46: =B46 -> I | M46: =C46 -> II | N46: =D46 -> III | O46: =E46 -> IV | P46: =F46 -> V
A47: A
B50: Wskaźniki egzaminu
B52: Liczba piszących
B53: Łatwość zestawu
B54: Średni wynik
B55: Mediana
B56: Modalna
B57: Wynik maksymalny
B58: Wynik minimalny
B59: Rozstęp wyników
B60: Odchylenie standardowe

Sheet KLASA E
A1: KLASA E | B1: liczba uczniów | C1: 19
A4: Zadanie | B4: 1 | C4: 2 | D4: 3 | E4: 4 | F4: 5 | G4: 6 | H4: 7 | I4: 8 | J4: 9 | K4: 10 | L4: 11 | M4: 12 | N4: 13 | O4: 14 | P4: 15 | Q4: 16 | R4: 17 | S4: 18 | T4: 19 | U4: 20 | V4: 21 I | W4: 21 II | X4: 22 I | Y4: 22 II | Z4: 23 | AA4: 24 | AB4: 25
A5: Standard | B5: I | C5: I | D5: I | E5: I | F5: III | G5: IV | H5: IV | I5: V | J5: V | K5: III | L5: III | M5: V | N5: V | O5: I | P5: I | Q5: I | R5: IV | S5: III | T5: V | U5: V | V5: III | W5: V | X5: III | Y5: V | Z5: I | AA5: I | AB5: II
A6: Max liczba punktów | B6: 1 | C6: 1 | D6: 1 | E6: 1 | F6: 1 | G6: 1 | H6: 2 | I6: 1 | J6: 1 | K6: 1 | L6: 1 | M6: 1 | N6: 1 | O6: 1 | P6: 1 | Q6: 1 | R6: 1 | S6: 1 | T6: 1 | U6: 1 | V6: 3 | W6: 1 | X6: 2 | Y6: 2 | Z6: 2 | AA6: 1 | AB6: 8 | AC6: suma | AD6: średnia
A7: E01 | B7: 1 | C7: 1 | D7: 1 | E7: 1 | F7: 0 | G7: 1 | H7: 0 | I7: 0 | J7: 1 | K7: 1 | L7: 0 | M7: 1 | N7: 1 | O7: 1 | P7: 1 | Q7: 0 | R7: 1 | S7: 0 | T7: 0 | U7: 0 | V7: 0 | W7: 0 | X7: 0 | Y7: 0 | Z7: 0 | AA7: 1 | AB7: 0
A8: E02 | B8: 1 | C8: 1 | D8: 1 | E8: 1 | F8: 0 | G8: 1 | H8: 0 | I8: 1 | J8: 1 | K8: 0 | L8: 1 | M8: 1 | N8: 1 | O8: 1 | P8: 1 | Q8: 0 | R8: 0 | S8: 0 | T8: 0 | U8: 0 | V8: 0 | W8: 0 | X8: 0 | Y8: 0 | Z8: 2 | AA8: 1 | AB8: 0
A9: E03 | B9: 1 | C9: 0 | D9: 1 | E9: 1 | F9: 0 | G9: 0 | H9: 0 | I9: 0 | J9: 1 | K9: 1 | L9: 1 | M9: 1 | N9: 1 | O9: 1 | P9: 1 | Q9: 1 | R9: 0 | S9: 0 | T9: 0 | U9: 0 | V9: 1 | W9: 0 | X9: 0 | Y9: 0 | Z9: 0 | AA9: 0 | AB9: 0
A10: E04 | B10: 1 | C10: 1 | D10: 1 | E10: 0 | F10: 0 | G10: 1 | H10: 2 | I10: 1 | J10: 1 | K10: 0 | L10: 1 | M10: 1 | N10: 0 | O10: 1 | P10: 1 | Q10: 0 | R10: 1 | S10: 1 | T10: 0 | U10: 1 | V10: 1 | W10: 0 | X10: 0 | Y10: 0 | Z10: 1 | AA10: 1 | AB10: 0
A11: E05 | B11: 1 | C11: 1 | D11: 1 | E11: 1 | F11: 0 | G11: 1 | H11: 2 | I11: 0 | J11: 1 | K11: 1 | L11: 1 | M11: 1 | N11: 1 | O11: 1 | P11: 1 | Q11: 1 | R11: 0 | S11: 0 | T11: 0 | U11: 0 | V11: 2 | W11: 0 | X11: 0 | Y11: 0 | Z11: 2 | AA11: 1 | AB11: 1
A12: E06 | B12: 1 | C12: 1 | D12: 1 | E12: 1 | F12: 0 | G12: 0 | H12: 0 | I12: 0 | J12: 1 | K12: 0 | L12: 1 | M12: 1 | N12: 1 | O12: 1 | P12: 1 | Q12: 0 | R12: 0 | S12: 1 | T12: 0 | U12: 0 | V12: 3 | W12: 1 | X12: 0 | Y12: 0 | Z12: 1 | AA12: 1 | AB12: 0
A13: E07 | B13: 1 | C13: 1 | D13: 1 | E13: 1 | F13: 0 | G13: 0 | H13: 0 | I13: 0 | J13: 1 | K13: 1 | L13: 1 | M13: 1 | N13: 1 | O13: 1 | P13: 1 | Q13: 1 | R13: 0 | S13: 0 | T13: 0 | U13: 0 | V13: 0 | W13: 0 | X13: 0 | Y13: 0 | Z13: 2 | AA13: 1 | AB13: 0
A14: E08 | B14: 1 | C14: 1 | D14: 1 | E14: 1 | F14: 0 | G14: 1 | H14: 2 | I14: 0 | J14: 1 | K14: 0 | L14: 1 | M14: 1 | N14: 1 | O14: 1 | P14: 1 | Q14: 0 | R14: 1 | S14: 1 | T14: 1 | U14: 0 | V14: 2 | W14: 0 | X14: 0 | Y14: 0 | Z14: 1 | AA14: 1 | AB14: 6
A15: E09 | B15: 1 | C15: 1 | D15: 0 | E15: 0 | F15: 1 | G15: 1 | H15: 0 | I15: 0 | J15: 0 | K15: 0 | L15: 0 | M15: 1 | N15: 1 | O15: 0 | P15: 1 | Q15: 1 | R15: 1 | S15: 0 | T15: 0 | U15: 0 | V15: 0 | W15: 0 | X15: 0 | Y15: 0 | Z15: 0 | AA15: 0 | AB15: 0
A16: E10 | B16: 1 | C16: 0 | D16: 1 | E16: 1 | F16: 1 | G16: 1 | H16: 0 | I16: 1 | J16: 1 | K16: 1 | L16: 1 | M16: 1 | N16: 1 | O16: 0 | P16: 1 | Q16: 0 | R16: 1 | S16: 0 | T16: 0 | U16: 0 | V16: 2 | W16: 0 | X16: 1 | Y16: 0 | Z16: 2 | AA16: 0 | AB16: 4
A17: E11 | B17: 1 | C17: 1 | D17: 1 | E17: 1 | F17: 0 | G17: 1 | H17: 2 | I17: 1 | J17: 1 | K17: 0 | L17: 0 | M17: 1 | N17: 1 | O17: 1 | P17: 1 | Q17: 0 | R17: 1 | S17: 1 | T17: 0 | U17: 0 | V17: 0 | W17: 0 | X17: 0 | Y17: 0 | Z17: 2 | AA17: 1 | AB17: 3
A18: E12 | B18: 0 | C18: 0 | D18: 0 | E18: 1 | F18: 1 | G18: 1 | H18: 0 | I18: 1 | J18: 1 | K18: 0 | L18: 0 | M18: 1 | N18: 1 | O18: 0 | P18: 1 | Q18: 0 | R18: 0 | S18: 0 | T18: 0 | U18: 0 | V18: 1 | W18: 0 | X18: 0 | Y18: 0 | Z18: 1 | AA18: 0 | AB18: 0
... A25: E19 | B25: 1 | C25: 0 | D25: 1 | E25: 1 | F25: 0 | G25: 1 | H25: 2 | I25: 0 | J25: 1 | K25: 0 | L25: 0 | M25: 1 | N25: 0 | O25: 0 | P25: 1 | Q25: 0 | R25: 0 | S25: 0 | T25: 1 | U25: 0 | V25: 2 | W25: 0 | X25: 0 | Y25: 0 | Z25: 2 | AA25: 0 | AB25: 5
A35: suma
A36: średnia
A37: wsółczynnik łatwości zadania
A38: poziom trudnosci zadania
B45: Max w standardach | G45: liczba punktów w standardach w klasia A | L45: Współczynnik łatwości standardów
A46: oddz | B46: I | C46: II | D46: III | E46: IV | F46: V | G46: =B46 -> I | H46: =C46 -> II | I46: =D46 -> III | J46: =E46 -> IV | K46: =F46 -> V | L46: =B46 -> I | M46: =C46 -> II | N46: =D46 -> III | O46: =E46 -> IV | P46: =F46 -> V
A47: A
B50: Wskaźniki egzaminu
B52: Liczba piszących
B53: Łatwość zestawu
B54: Średni wynik
B55: Mediana
B56: Modalna
B57: Wynik maksymalny
B58: Wynik minimalny
B59: Rozstęp wyników
B60: Odchylenie standardowe

Sheet KLASA F
A1: KLASA F | B1: liczba uczniów | C1: 22
A3: Zadanie | B3: 1 | C3: 2 | D3: 3 | E3: 4 | F3: 5 | G3: 6 | H3: 7 | I3: 8 | J3: 9 | K3: 10 | L3: 11 | M3: 12 | N3: 13 | O3: 14 | P3: 15 | Q3: 16 | R3: 17 | S3: 18 | T3: 19 | U3: 20 | V3: 21 I | W3: 21 II | X3: 22 I | Y3: 22 II | Z3: 23 | AA3: 24 | AB3: 25
A4: Standard | B4: I | C4: I | D4: I | E4: I | F4: III | G4: IV | H4: IV | I4: V | J4: V | K4: III | L4: III | M4: V | N4: V | O4: I | P4: I | Q4: I | R4: IV | S4: III | T4: V | U4: V | V4: III | W4: V | X4: III | Y4: V | Z4: I | AA4: I | AB4: II
A5: Max liczba punktów | B5: 1 | C5: 1 | D5: 1 | E5: 1 | F5: 1 | G5: 1 | H5: 2 | I5: 1 | J5: 1 | K5: 1 | L5: 1 | M5: 1 | N5: 1 | O5: 1 | P5: 1 | Q5: 1 | R5: 1 | S5: 1 | T5: 1 | U5: 1 | V5: 3 | W5: 1 | X5: 2 | Y5: 2 | Z5: 2 | AA5: 1 | AB5: 8 | AC5: suma | AD5: średnia
A6: F01 | B6: 1 | C6: 1 | D6: 1 | E6: 1 | F6: 0 | G6: 1 | H6: 2 | I6: 1 | J6: 1 | K6: 1 | L6: 1 | M6: 1 | N6: 1 | O6: 1 | P6: 1 | Q6: 0 | R6: 1 | S6: 1 | T6: 0 | U6: 0 | V6: 2 | W6: 0 | X6: 2 | Y6: 0 | Z6: 2 | AA6: 1 | AB6: 4
A7: F02 | B7: 1 | C7: 1 | D7: 1 | E7: 1 | F7: 1 | G7: 0 | H7: 1 | I7: 0 | J7: 1 | K7: 0 | L7: 1 | M7: 1 | N7: 0 | O7: 0 | P7: 1 | Q7: 0 | R7: 1 | S7: 1 | T7: 0 | U7: 0 | V7: 0 | W7: 0 | X7: 0 | Y7: 0 | Z7: 1 | AA7: 0 | AB7: 3
A8: F03 | B8: 1 | C8: 1 | D8: 1 | E8: 0 | F8: 0 | G8: 1 | H8: 0 | I8: 0 | J8: 1 | K8: 0 | L8: 0 | M8: 1 | N8: 0 | O8: 1 | P8: 1 | Q8: 0 | R8: 0 | S8: 0 | T8: 0 | U8: 0 | V8: 0 | W8: 0 | X8: 0 | Y8: 0 | Z8: 2 | AA8: 0 | AB8: 2
A9: F04 | B9: 1 | C9: 1 | D9: 1 | E9: 0 | F9: 0 | G9: 1 | H9: 1 | I9: 1 | J9: 0 | K9: 0 | L9: 0 | M9: 1 | N9: 1 | O9: 1 | P9: 1 | Q9: 0 | R9: 0 | S9: 1 | T9: 0 | U9: 0 | V9: 3 | W9: 0 | X9: 0 | Y9: 0 | Z9: 2 | AA9: 1 | AB9: 3
A10: F05 | B10: 1 | C10: 1 | D10: 1 | E10: 1 | F10: 0 | G10: 1 | H10: 2 | I10: 0 | J10: 0 | K10: 0 | L10: 1 | M10: 1 | N10: 1 | O10: 1 | P10: 1 | Q10: 0 | R10: 1 | S10: 1 | T10: 1 | U10: 0 | V10: 0 | W10: 0 | X10: 0 | Y10: 0 | Z10: 2 | AA10: 0 | AB10: 2
A11: F06 | B11: 1 | C11: 1 | D11: 1 | E11: 1 | F11: 1 | G11: 1 | H11: 2 | I11: 1 | J11: 1 | K11: 1 | L11: 1 | M11: 1 | N11: 1 | O11: 1 | P11: 1 | Q11: 1 | R11: 1 | S11: 1 | T11: 1 | U11: 1 | V11: 3 | W11: 1 | X11: 2 | Y11: 2 | Z11: 2 | AA11: 1 | AB11: 6
A12: F07 | B12: 1 | C12: 0 | D12: 1 | E12: 1 | F12: 0 | G12: 1 | H12: 2 | I12: 0 | J12: 1 | K12: 1 | L12: 0 | M12: 1 | N12: 1 | O12: 1 | P12: 1 | Q12: 1 | R12: 1 | S12: 1 | T12: 0 | U12: 1 | V12: 3 | W12: 1 | X12: 1 | Y12: 0 | Z12: 2 | AA12: 0 | AB12: 5
A13: F08 | B13: 1 | C13: 1 | D13: 1 | E13: 0 | F13: 0 | G13: 0 | H13: 2 | I13: 1 | J13: 1 | K13: 0 | L13: 1 | M13: 1 | N13: 0 | O13: 0 | P13: 1 | Q13: 0 | R13: 1 | S13: 1 | T13: 1 | U13: 0 | V13: 0 | W13: 0 | X13: 0 | Y13: 0 | Z13: 2 | AA13: 0 | AB13: 3
A14: F09 | B14: 1 | C14: 1 | D14: 1 | E14: 1 | F14: 0 | G14: 1 | H14: 0 | I14: 1 | J14: 1 | K14: 1 | L14: 0 | M14: 1 | N14: 1 | O14: 1 | P14: 1 | Q14: 0 | R14: 1 | S14: 0 | T14: 0 | U14: 0 | V14: 0 | W14: 0 | X14: 0 | Y14: 0 | Z14: 2 | AA14: 0 | AB14: 1
A15: F10 | B15: 1 | C15: 1 | D15: 1 | E15: 0 | F15: 0 | G15: 1 | H15: 2 | I15: 0 | J15: 1 | K15: 1 | L15: 1 | M15: 1 | N15: 1 | O15: 1 | P15: 1 | Q15: 0 | R15: 1 | S15: 1 | T15: 0 | U15: 1 | V15: 3 | W15: 1 | X15: 0 | Y15: 0 | Z15: 2 | AA15: 1 | AB15: 2
A16: F11 | B16: 1 | C16: 1 | D16: 1 | E16: 0 | F16: 0 | G16: 1 | H16: 1 | I16: 0 | J16: 1 | K16: 0 | L16: 1 | M16: 1 | N16: 1 | O16: 1 | P16: 1 | Q16: 0 | R16: 1 | S16: 1 | T16: 1 | U16: 0 | V16: 3 | W16: 0 | X16: 2 | Y16: 0 | Z16: 1 | AA16: 1 | AB16: 4
A17: F12 | B17: 1 | C17: 1 | D17: 1 | E17: 1 | F17: 0 | G17: 1 | H17: 1 | I17: 0 | J17: 1 | K17: 1 | L17: 0 | M17: 1 | N17: 0 | O17: 1 | P17: 1 | Q17: 1 | R17: 0 | S17: 1 | T17: 0 | U17: 0 | V17: 0 | W17: 0 | X17: 0 | Y17: 0 | Z17: 0 | AA17: 0 | AB17: 1
... A27: F22 | B27: 1 | C27: 1 | D27: 1 | E27: 1 | F27: 0 | G27: 1 | H27: 0 | I27: 1 | J27: 1 | K27: 0 | L27: 0 | M27: 0 | N27: 0 | O27: 0 | P27: 0 | Q27: 0 | R27: 0 | S27: 0 | T27: 0 | U27: 1 | V27: 3 | W27: 0 | X27: 1 | Y27: 0 | Z27: 2 | AA27: 0 | AB27: 3
A35: suma
A36: średnia
A37: wsółczynnik łatwości zadania
A38: poziom trudnosci zadania
B45: Max w standardach | G45: liczba punktów w standardach w klasia A | L45: Współczynnik łatwości standardów
A46: oddz | B46: I | C46: II | D46: III | E46: IV | F46: V | G46: =B46 -> I | H46: =C46 -> II | I46: =D46 -> III | J46: =E46 -> IV | K46: =F46 -> V | L46: =B46 -> I | M46: =C46 -> II | N46: =D46 -> III | O46: =E46 -> IV | P46: =F46 -> V
A47: A
B50: Wskaźniki egzaminu
B52: Liczba piszących
B53: Łatwość zestawu
B54: Średni wynik
B55: Mediana
B56: Modalna
B57: Wynik maksymalny
B58: Wynik minimalny
B59: Rozstęp wyników
B60: Odchylenie standardowe

Sheet SZKOŁA
A2: ucz
A3: A01 | B3: ='KLASA A'!AC6 -> 35
A4: A02 | B4: ='KLASA A'!AC7 -> 16 | E4: Wskaźniki egzaminu | L4: Zadanie | M4: 1 | N4: 2 | O4: 3 | P4: 4 | Q4: 5 | R4: 6 | S4: 7 | T4: 8 | U4: 9 | V4: 10 | W4: 11 | X4: 12 | Y4: 13 | Z4: 14 | AA4: 15 | AB4: 16 | AC4: 17 | AD4: 18 | AE4: 19 | AF4: 20 | AG4: 21 I | AH4: 21 II | AI4: 22 I | AJ4: 22 II | AK4: 23 | AL4: 24 | AM4: 25
A5: A03 | B5: ='KLASA A'!AC8 -> 34 | L5: Standard | M5: I | N5: I | O5: I | P5: I | Q5: III | R5: IV | S5: IV | T5: V | U5: V | V5: III | W5: III | X5: V | Y5: V | Z5: I | AA5: I | AB5: I | AC5: IV | AD5: III | AE5: V | AF5: V | AG5: III | AH5: V | AI5: III | AJ5: V | AK5: I | AL5: I | AM5: II
A6: A04 | B6: ='KLASA A'!AC9 -> 18 | E6: Liczba piszących | I6: 144 | L6: Max liczba punktów | M6: 1 | N6: 1 | O6: 1 | P6: 1 | Q6: 1 | R6: 1 | S6: 2 | T6: 1 | U6: 1 | V6: 1 | W6: 1 | X6: 1 | Y6: 1 | Z6: 1 | AA6: 1 | AB6: 1 | AC6: 1 | AD6: 1 | AE6: 1 | AF6: 1 | AG6: 3 | AH6: 1 | AI6: 2 | AJ6: 2 | AK6: 2 | AL6: 1 | AM6: 8 | AN6: suma | AO6: średnia
A7: A05 | B7: ='KLASA A'!AC10 -> 11 | E7: Łatwość zestawu | L7: Klasa A
A8: A06 | B8: ='KLASA A'!AC11 -> 22 | E8: Średni wynik | L8: Klasa B
A9: A07 | B9: ='KLASA A'!AC12 -> 24 | E9: Mediana | L9: Klasa C
A10: A08 | B10: ='KLASA A'!AC13 -> 20 | E10: Modalna | L10: Klasa D
A11: A09 | B11: ='KLASA A'!AC14 -> 17 | E11: Wynik maksymalny | L11: Klasa E
A12: A10 | B12: ='KLASA A'!AC15 -> 10 | E12: Wynik minimalny | L12: Klasa F
A13: A11 | B13: ='KLASA A'!AC16 -> 24 | E13: Rozstęp wyników
A14: A12 | B14: ='KLASA A'!AC17 -> 22 | E14: Odchylenie standardowe
A15: A13 | B15: ='KLASA A'!AC18 -> 19
A16: A14 | B16: ='KLASA A'!AC19 -> 23 | L16: suma
A17: A15 | B17: ='KLASA A'!AC20 -> 15 | L17: średnia
A18: A16 | B18: ='KLASA A'!AC21 -> 16 | L18: wsółczynnik łatwości zadania
A19: A17 | B19: ='KLASA A'!AC22 -> 33 | L19: poziom trudnosci zadania
A20: A18 | B20: ='KLASA A'!AC23 -> 25
A21: A19 | B21: ='KLASA A'!AC24 -> 17
A22: A20 | B22: ='KLASA A'!AC25 -> 22
A23: A21 | B23: ='KLASA A'!AC26 -> 29 | M23: standardy | N23: max liczba punktów | O23: liczba punktów w szkole | P23: średnia
A24: A22 | B24: ='KLASA A'!AC27 -> 23 | L24: I-Czytanie | M24: I
A25: A23 | B25: ='KLASA A'!AC28 -> 12 | L25: II-Pisanie | M25: II
A26: A24 | B26: ='KLASA A'!AC29 -> 17 | L26: III-Rozumowanie | M26: III
A27: A25 | B27: ='KLASA A'!AC30 -> 31 | L27: IV-Korzystanie z informacji | M27: IV
L28: V-Wiedza w praktyce | M28: V
A35: B01 | B35: ='KLASA B'!AC6 -> 14
A36: B02 | B36: ='KLASA B'!AC7 -> 19
A37: B03 | B37: ='KLASA B'!AC8 -> 14
A38: B04 | B38: ='KLASA B'!AC9 -> 21
A39: B05 | B39: ='KLASA B'!AC10 -> 26
A40: B06 | B40: ='KLASA B'!AC11 -> 31
A41: B07 | B41: ='KLASA B'!AC12 -> 14
A42: B08 | B42: ='KLASA B'!AC13 -> 22
A43: B09 | B43: ='KLASA B'!AC14 -> 22
A44: B10 | B44: ='KLASA B'!AC15 -> 10
A45: B11 | B45: ='KLASA B'!AC16 -> 27
A46: B12 | B46: ='KLASA B'!AC17 -> 23
... A60: B26 | B60: ='KLASA B'!AC31 -> 16
...
